https://stepik.org/lesson/%D0%9E%D1%88%D0%B8%D0%B1%D0%BA%D0%B8-%D0%B8-%D0%B8%D1%81%D0%BA%D0%BB%D1%8E%D1%87%D0%B5%D0%BD%D0%B8%D1%8F-24463/step/6?course=Python-%D0%BE%D1%81%D0%BD%D0%BE%D0%B2%D1%8B-%D0%B8-%D0%BF%D1%80%D0%B8%D0%BC%D0%B5%D0%BD%D0%B5%D0%BD%D0%B8%D0%B5&unit=6771



Вашей программе будет доступна функция foo, которая может бросать исключения.

Вам необходимо написать код, который запускает эту функцию, затем ловит исключения ArithmeticError, AssertionError, ZeroDivisionError и выводит имя пойманного исключения.

Пример решения, которое вы должны отправить на проверку.

try:
    foo()
except Exception:
    print("Exception")
except BaseException:
    print("BaseException")

Подсказка: https://docs.python.org/3/library/exceptions.html#exception-hierarchy

